Workbook

Sheet Column Forces
B1: Story | C1: Column | D1: Load | E1: Loc | F1: P | G1: V2 | H1: V3 | I1: T | J1: M2 | K1: M3
A2: =+CONCATENATE(B2,D2,E2) -> GROUND FLUL10 | B2: GROUND FL | C2: C1 | D2: UL1 | E2: 0 | F2: -615.43 | G2: 185.03 | H2: -4.04 | I2: -0.065 | J2: -12.325 | K2: 301.468
A3: =+CONCATENATE(B3,D3,E3) -> GROUND FLUL11.615 | B3: GROUND FL | C3: C1 | D3: UL1 | E3: 1.615 | F3: -615.43 | G3: 185.03 | H3: -4.04 | I3: -0.065 | J3: -5.679 | K3: 1.952
A4: =+CONCATENATE(B4,D4,E4) -> GROUND FLUL13.23 | B4: GROUND FL | C4: C1 | D4: UL1 | E4: 3.23 | F4: -615.43 | G4: 185.03 | H4: -4.04 | I4: -0.065 | J4: 0.993 | K4: -297.574
A5: =+CONCATENATE(B5,D5,E5) -> GROUND FLUL20 | B5: GROUND FL | C5: C1 | D5: UL2 | E5: 0 | F5: 2370.53 | G5: 14.42 | H5: 160.88 | I5: -0.105 | J5: 263.82 | K5: 23.739
A6: =+CONCATENATE(B6,D6,E6) -> GROUND FLUL21.615 | B6: GROUND FL | C6: C1 | D6: UL2 | E6: 1.615 | F6: 2370.53 | G6: 14.42 | H6: 160.88 | I6: -0.105 | J6: 2.141 | K6: 0.449
A7: =+CONCATENATE(B7,D7,E7) -> GROUND FLUL23.23 | B7: GROUND FL | C7: C1 | D7: UL2 | E7: 3.23 | F7: 2370.53 | G7: 14.42 | H7: 160.88 | I7: -0.105 | J7: -259.548 | K7: -22.844
A8: =+CONCATENATE(B8,D8,E8) -> GROUND FLUL30 | B8: GROUND FL | C8: C1 | D8: UL3 | E8: 0 | F8: 23.31 | G8: 7.38 | H8: 8.02 | I8: 0.079 | J8: 9.74 | K8: 12.016
A9: =+CONCATENATE(B9,D9,E9) -> GROUND FLUL31.615 | B9: GROUND FL | C9: C1 | D9: UL3 | E9: 1.615 | F9: 23.31 | G9: 7.38 | H9: 8.02 | I9: 0.079 | J9: -3.235 | K9: 0.076
A10: =+CONCATENATE(B10,D10,E10) -> GROUND FLUL33.23 | B10: GROUND FL | C10: C1 | D10: UL3 | E10: 3.23 | F10: 23.31 | G10: 7.38 | H10: 8.02 | I10: 0.079 | J10: -16.194 | K10: -11.864
A11: =+CONCATENATE(B11,D11,E11) -> BASE 1 FLUL10 | B11: BASE 1 FL | C11: C1 | D11: UL1 | E11: 0 | F11: -1677.84 | G11: 81.19 | H11: 10.59 | I11: -0.034 | J11: 8.294 | K11: 133.056
A12: =+CONCATENATE(B12,D12,E12) -> BASE 1 FLUL11.615 | B12: BASE 1 FL | C12: C1 | D12: UL1 | E12: 1.615 | F12: -1677.84 | G12: 81.19 | H12: 10.59 | I12: -0.034 | J12: -8.782 | K12: 0.98
A13: =+CONCATENATE(B13,D13,E13) -> BASE 1 FLUL13.23 | B13: BASE 1 FL | C13: C1 | D13: UL1 | E13: 3.23 | F13: -1677.84 | G13: 81.19 | H13: 10.59 | I13: -0.034 | J13: -25.764 | K13: -131.107
... A4045: =+CONCATENATE(B4045,D4045,E4045) -> BASE 3 FLUL32.81 | B4045: BASE 3 FL | C4045: C45 | D4045: UL3 | E4045: 2.81 | F4045: -3208.6 | G4045: -273.34 | H4045: 373.76 | I4045: 2.257 | J4045: -528.091 | K4045: 380.743

Sheet Shear Wall Forces
B1: Story | C1: Pier | D1: Load | E1: Loc | F1: P | G1: V2 | H1: V3 | I1: T | J1: M2 | K1: M3
A2: =+CONCATENATE(B2,D2,E2) -> ROOF FLUL1Top | B2: ROOF FL | C2: P1 | D2: UL1 | E2: Top | F2: -19406.26 | G2: -2178.14 | H2: -29129.58 | I2: -156395.96 | J2: 338849.28 | K2: -22472.16
A3: =+CONCATENATE(B3,D3,E3) -> ROOF FLUL1Bottom | B3: ROOF FL | C3: P1 | D3: UL1 | E3: Bottom | F3: -19406.26 | G3: -2178.14 | H3: -29129.58 | I3: -155497.1 | J3: 199798.84 | K3: -32434.246
A4: =+CONCATENATE(B4,D4,E4) -> ROOF FLUL2Top | B4: ROOF FL | C4: P1 | D4: UL2 | E4: Top | F4: -50460.92 | G4: -38403.99 | H4: 903.78 | I4: 2937.565 | J4: 6059.512 | K4: -481116.42
A5: =+CONCATENATE(B5,D5,E5) -> ROOF FLUL2Bottom | B5: ROOF FL | C5: P1 | D5: UL2 | E5: Bottom | F5: -50460.92 | G5: -38403.99 | H5: 903.78 | I5: 2931.323 | J5: 10151.799 | K5: -645661.62
A6: =+CONCATENATE(B6,D6,E6) -> ROOF FLUL3Top | B6: ROOF FL | C6: P1 | D6: UL3 | E6: Top | F6: 125.18 | G6: 61.75 | H6: 1094.06 | I6: 10589.219 | J6: -11610.484 | K6: 241.946
A7: =+CONCATENATE(B7,D7,E7) -> ROOF FLUL3Bottom | B7: ROOF FL | C7: P1 | D7: UL3 | E7: Bottom | F7: 125.18 | G7: 61.75 | H7: 1094.06 | I7: 10726.403 | J7: -6891.311 | K7: 516.488
A8: =+CONCATENATE(B8,D8,E8) -> TERRACE FLUL1Top | B8: TERRACE FL | C8: P1 | D8: UL1 | E8: Top | F8: -36564.91 | G8: 13206.06 | H8: -95094.7 | I8: -390640.54 | J8: 637174.39 | K8: -64986.039
A9: =+CONCATENATE(B9,D9,E9) -> TERRACE FLUL1Bottom | B9: TERRACE FL | C9: P1 | D9: UL1 | E9: Bottom | F9: 35933 | G9: 125663.69 | H9: -107829.18 | I9: -425585.66 | J9: 322971.15 | K9: 67284.287
A10: =+CONCATENATE(B10,D10,E10) -> TERRACE FLUL2Top | B10: TERRACE FL | C10: P1 | D10: UL2 | E10: Top | F10: -69751.47 | G10: 71582.17 | H10: 5684.97 | I10: 13205.412 | J10: 7655.874 | K10: -825821.59
A11: =+CONCATENATE(B11,D11,E11) -> TERRACE FLUL2Bottom | B11: TERRACE FL | C11: P1 | D11: UL2 | E11: Bottom | F11: -69759.53 | G11: 73217.46 | H11: 8684.46 | I11: 9495.898 | J11: 18138.133 | K11: -568835.45
A12: =+CONCATENATE(B12,D12,E12) -> TERRACE FLUL3Top | B12: TERRACE FL | C12: P1 | D12: UL3 | E12: Top | F12: 652.86 | G12: -593.34 | H12: 1815.62 | I12: 82544.977 | J12: -17003.645 | K12: 906.578
A13: =+CONCATENATE(B13,D13,E13) -> TERRACE FLUL3Bottom | B13: TERRACE FL | C13: P1 | D13: UL3 | E13: Bottom | F13: -346.7 | G13: -1297.24 | H13: 2792.09 | I13: 81225.812 | J13: -7877.833 | K13: -979.495
... A127: =+CONCATENATE(B127,D127,E127) -> BASE 3 FLUL3Bottom | B127: BASE 3 FL | C127: P1 | D127: UL3 | E127: Bottom | F127: -3490.7 | G127: 1118.75 | H127: -976.77 | I127: 778049.39 | J127: 287176.45 | K127: 36009.919
A128: /

Sheet Base Reactions
B2: Story | C2: Point | D2: Load | E2: FX | F2: FY | G2: FZ | H2: MX | I2: MY | J2: MZ
B3: BASE | C3: 6 | D3: EQX | E3: -1.17 | F3: -0.25 | G3: -217.31 | H3: 0.405 | I3: -1.867 | J3: 0.003
B4: BASE | C4: 6 | D4: EQY | E4: 0.03 | F4: -1.06 | G4: -107.71 | H4: 1.779 | I4: 0.111 | J4: 0.001
B5: BASE | C5: 6 | D5: EQXN | E5: -1.85 | F5: 0.13 | G5: -256.6 | H5: -0.242 | I5: -2.949 | J5: -0.003
B6: BASE | C6: 6 | D6: EQYN | E6: 0.41 | F6: -1.28 | G6: -85.65 | H6: 2.144 | I6: 0.722 | J6: 0.005
B7: BASE | C7: 6 | D7: UL1 | E7: -962.96 | F7: -81.7 | G7: -140083.52 | H7: 118.595 | I7: -1543.111 | J7: 0.582
B8: BASE | C8: 6 | D8: UL2 | E8: 10.52 | F8: -747.04 | G8: -64257.24 | H8: 1241.374 | I8: 50.344 | J8: 0.774
B9: BASE | C9: 6 | D9: UL3 | E9: -134.44 | F9: 75.78 | G9: -6837.48 | H9: -129.128 | I9: -214.987 | J9: -1.113
B10: BASE | C10: 6 | D10: RSEQX | E10: 1.73 | F10: 0.43 | G10: 212.19 | H10: 0.711 | I10: 2.769 | J10: 0.006
B11: BASE | C11: 6 | D11: RSEQY | E11: 0.84 | F11: 1.36 | G11: 69.38 | H11: 2.256 | I11: 1.375 | J11: 0.007
B12: BASE | C12: 6 | D12: RSEQXELAS | E12: 4.24 | F12: 1.11 | G12: 499.61 | H12: 1.852 | I12: 6.812 | J12: 0.015
B13: BASE | C13: 6 | D13: RSEQYELAS | E13: 2.06 | F13: 3.21 | G13: 155.39 | H13: 5.328 | I13: 3.345 | J13: 0.018
B14: BASE | C14: 6 | D14: SESMASSX | E14: 1.36 | F14: 0.05 | G14: 830.47 | H14: -0.036 | I14: 1.722 | J14: 0.004
... B3977: BASE | C3977: 789 | D3977: CORSY1DL MIN | E3977: -4.14 | F3977: -2.17 | G3977: 413.89 | H3977: -4.059 | I3977: -6.533 | J3977: -0.018

Sheet STORY DATA
B1: Storey Height for Building
B3: Story | C3: Height | D3: Elevation | E3: SimilarTo
B4: UP ROOF FL | C4: 3.2 | D4: 36 | E4: None
B5: ROOF FL | C5: 3.2 | D5: 32.8 | E5: None
B6: 9TH FL | C6: 3.2 | D6: 29.6 | E6: 3RD FL
B7: 8TH FL | C7: 3.2 | D7: 26.4 | E7: 3RD FL
B8: 7TH FL | C8: 3.2 | D8: 23.2 | E8: 3RD FL
B9: 6TH FL | C9: 3.2 | D9: 20 | E9: 3RD FL
B10: 5TH FL | C10: 3.2 | D10: 16.8 | E10: 3RD FL
B11: 4TH FL | C11: 3.2 | D11: 13.6 | E11: 3RD FL
B12: 3RD FL | C12: 3.2 | D12: 10.4 | E12: None
B13: 2ND FL | C13: 3.2 | D13: 7.2 | E13: 3RD FL
B14: 1ST FL | C14: 4 | D14: 4 | E14: None
B15: GROUND FL | C15: 3.04 | D15: 0 | E15: None
... B17: BASE | C17: 0 | D17: -6.04 | E17: None

Sheet Diaphram Drift
B1: Project : | C1: =+DISPLACEMENT!C1 -> BAHRU SARBET MODEL 1-3 q=1
B2: Client : | C2: =+DISPLACEMENT!C2 -> ATO BAHRU
B3: Consultant : | C3: =+[1]DISPLACEMENT!C3 -> 0
B4: Designed by : | C4: =+[1]DISPLACEMENT!C4 -> Sofonias Bezabeh
B6: Diaphram Dispacement
B8: Story | C8: Item | D8: Load | E8: Point | F8: X | G8: Y | H8: Z | I8: DriftX | J8: DriftY
B9: UP ROOF FL | C9: Diaph D15 X | D9: EQX | E9: 603 | F9: 12.7 | G9: 26.7 | H9: 40.8 | I9: 0.001003
B10: UP ROOF FL | C10: Diaph D15 Y | D10: EQX | E10: 357 | F10: 8.35 | G10: 16.7 | H10: 40.8 | J10: 3e-05
B11: UP ROOF FL | C11: Diaph D15 X | D11: EQY | E11: 603 | F11: 12.7 | G11: 26.7 | H11: 40.8 | I11: 6.9e-05
B12: UP ROOF FL | C12: Diaph D15 Y | D12: EQY | E12: 407 | F12: 8.35 | G12: 19.2 | H12: 40.8 | J12: 0.000496
B13: UP ROOF FL | C13: Diaph D15 X | D13: EQXN | E13: 244 | F13: 12.7 | G13: 11.2 | H13: 40.8 | I13: 0.001063
B14: UP ROOF FL | C14: Diaph D15 Y | D14: EQXN | E14: 407 | F14: 8.35 | G14: 19.2 | H14: 40.8 | J14: 3.9e-05
B15: UP ROOF FL | C15: Diaph D15 X | D15: EQYN | E15: 603 | F15: 12.7 | G15: 26.7 | H15: 40.8 | I15: 0.000169
B16: UP ROOF FL | C16: Diaph D15 Y | D16: EQYN | E16: 407 | F16: 8.35 | G16: 19.2 | H16: 40.8 | J16: 0.00053
B17: UP ROOF FL | C17: Diaph D15 X | D17: UL1 | E17: 244 | F17: 12.7 | G17: 11.2 | H17: 40.8 | I17: 0.774941
B18: UP ROOF FL | C18: Diaph D15 Y | D18: UL1 | E18: 337 | F18: 8.35 | G18: 15.5 | H18: 40.8 | J18: 0.044055
B19: UP ROOF FL | C19: Diaph D15 X | D19: UL2 | E19: 603 | F19: 12.7 | G19: 26.7 | H19: 40.8 | I19: 0.092912
B20: UP ROOF FL | C20: Diaph D15 Y | D20: UL2 | E20: 407 | F20: 8.35 | G20: 19.2 | H20: 40.8 | J20: 0.638206
B21: UP ROOF FL | C21: Diaph D15 X | D21: UL3 | E21: 603 | F21: 12.7 | G21: 26.7 | H21: 40.8 | I21: 0.09432
B22: UP ROOF FL | C22: Diaph D15 Y | D22: UL3 | E22: 287 | F22: 8.35 | G22: 13.634 | H22: 40.8 | J22: 0.036129
B23: UP ROOF FL | C23: Diaph D15 X | D23: RSEQX | E23: 244 | F23: 12.7 | G23: 11.2 | H23: 40.8 | I23: 0.001155
B24: UP ROOF FL | C24: Diaph D15 Y | D24: RSEQX | E24: 603 | F24: 12.7 | G24: 26.7 | H24: 40.8 | J24: 0.000126
B25: UP ROOF FL | C25: Diaph D15 X | D25: RSEQY | E25: 603 | F25: 12.7 | G25: 26.7 | H25: 40.8 | I25: 0.000299
B26: UP ROOF FL | C26: Diaph D15 Y | D26: RSEQY | E26: 407 | F26: 8.35 | G26: 19.2 | H26: 40.8 | J26: 0.000823
B27: UP ROOF FL | C27: Diaph D15 X | D27: RSEQXELAS | E27: 244 | F27: 12.7 | G27: 11.2 | H27: 40.8 | I27: 0.002906
B28: UP ROOF FL | C28: Diaph D15 Y | D28: RSEQXELAS | E28: 603 | F28: 12.7 | G28: 26.7 | H28: 40.8 | J28: 0.000326
B29: UP ROOF FL | C29: Diaph D15 X | D29: RSEQYELAS | E29: 603 | F29: 12.7 | G29: 26.7 | H29: 40.8 | I29: 0.000745
B30: UP ROOF FL | C30: Diaph D15 Y | D30: RSEQYELAS | E30: 407 | F30: 8.35 | G30: 19.2 | H30: 40.8 | J30: 0.002141
B31: UP ROOF FL | C31: Diaph D15 X | D31: SESMASSX | E31: 603 | F31: 12.7 | G31: 26.7 | H31: 40.8 | I31: 0.000341
B32: UP ROOF FL | C32: Diaph D15 Y | D32: SESMASSX | E32: 603 | F32: 12.7 | G32: 26.7 | H32: 40.8 | J32: 7.8e-05
B33: UP ROOF FL | C33: Diaph D15 X | D33: SESMASSY | E33: 603 | F33: 12.7 | G33: 26.7 | H33: 40.8 | I33: 0.000341
B34: UP ROOF FL | C34: Diaph D15 Y | D34: SESMASSY | E34: 603 | F34: 12.7 | G34: 26.7 | H34: 40.8 | J34: 7.8e-05
B35: UP ROOF FL | C35: Diaph D15 X | D35: SESIMPX | E35: 244 | F35: 12.7 | G35: 11.2 | H35: 40.8 | I35: 0.000145
B36: UP ROOF FL | C36: Diaph D15 Y | D36: SESIMPX | E36: 525 | F36: 12.7 | G36: 23.1 | H36: 40.8 | J36: 3e-06
B37: UP ROOF FL | C37: Diaph D15 X | D37: SESIMPY | E37: 603 | F37: 12.7 | G37: 26.7 | H37: 40.8 | I37: 1.8e-05
B38: UP ROOF FL | C38: Diaph D15 Y | D38: SESIMPY | E38: 407 | F38: 8.35 | G38: 19.2 | H38: 40.8 | J38: 7e-05
B39: UP ROOF FL | C39: Diaph D15 X | D39: COMBX1 | E39: 603 | F39: 12.7 | G39: 26.7 | H39: 40.8 | I39: 0.001499
B40: UP ROOF FL | C40: Diaph D15 Y | D40: COMBX1 | E40: 357 | F40: 8.35 | G40: 16.7 | H40: 40.8 | J40: 0.000225
B41: UP ROOF FL | C41: Diaph D15 X | D41: COMBX2 | E41: 603 | F41: 12.7 | G41: 26.7 | H41: 40.8 | I41: 0.001457
B42: UP ROOF FL | C42: Diaph D15 Y | D42: COMBX2 | E42: 603 | F42: 12.7 | G42: 26.7 | H42: 40.8 | J42: 0.000212
...

Sheet DISPLACEMENT
B1: Project : | C1: BAHRU SARBET MODEL 1-3 q=1
B2: Client : | C2: ATO BAHRU
B3: Consultant :
B4: Designed by : | C4: Sofonias Bezabeh
B6: Diaphram Dispacement
B8: Story | C8: Diaphragm | D8: Load | E8: UX | F8: UY | G8: UZ | H8: RX | I8: RY | J8: RZ | K8: Point | L8: X | M8: Y | N8: Z
B9: UP ROOF FL | C9: D15 | D9: EQX | E9: 0.0667 | F9: 0.0001 | G9: 0 | H9: 0 | I9: 0 | J9: -0.00036 | K9: 1603 | L9: 10.673 | M9: 18.907 | N9: 40.8
B10: UP ROOF FL | C10: D15 | D10: EQY | E10: 0.0004 | F10: 0.0743 | G10: 0 | H10: 0 | I10: 0 | J10: -8e-05 | K10: 1603 | L10: 10.673 | M10: 18.907 | N10: 40.8
B11: UP ROOF FL | C11: D15 | D11: EQXN | E11: 0.0643 | F11: 0.0005 | G11: 0 | H11: 0 | I11: 0 | J11: 0.00117 | K11: 1603 | L11: 10.673 | M11: 18.907 | N11: 40.8
B12: UP ROOF FL | C12: D15 | D12: EQYN | E12: 0.0017 | F12: 0.0741 | G12: 0 | H12: 0 | I12: 0 | J12: -0.00093 | K12: 1603 | L12: 10.673 | M12: 18.907 | N12: 40.8
B13: UP ROOF FL | C13: D15 | D13: UL1 | E13: 36.0479 | F13: 0.0592 | G13: 0 | H13: 0 | I13: 0 | J13: 0.10033 | K13: 1603 | L13: 10.673 | M13: 18.907 | N13: 40.8
B14: UP ROOF FL | C14: D15 | D14: UL2 | E14: 0.2036 | F14: 41.1579 | G14: 0 | H14: 0 | I14: 0 | J14: -0.05851 | K14: 1603 | L14: 10.673 | M14: 18.907 | N14: 40.8
B15: UP ROOF FL | C15: D15 | D15: UL3 | E15: -0.354 | F15: 0.0411 | G15: 0 | H15: 0 | I15: 0 | J15: 0.2646 | K15: 1603 | L15: 10.673 | M15: 18.907 | N15: 40.8
B16: UP ROOF FL | C16: D15 | D16: RSEQX | E16: 0.051 | F16: 0.0079 | G16: 0 | H16: 0 | I16: 0 | J16: 0.00154 | K16: 1603 | L16: 10.673 | M16: 18.907 | N16: 40.8
B17: UP ROOF FL | C17: D15 | D17: RSEQY | E17: 0.0069 | F17: 0.0565 | G17: 0 | H17: 0 | I17: 0 | J17: 0.00138 | K17: 1603 | L17: 10.673 | M17: 18.907 | N17: 40.8
B18: UP ROOF FL | C18: D15 | D18: RSEQXELAS | E18: 0.1174 | F18: 0.0181 | G18: 0 | H18: 0 | I18: 0 | J18: 0.00362 | K18: 1603 | L18: 10.673 | M18: 18.907 | N18: 40.8
B19: UP ROOF FL | C19: D15 | D19: RSEQYELAS | E19: 0.0161 | F19: 0.1154 | G19: 0 | H19: 0 | I19: 0 | J19: 0.00297 | K19: 1603 | L19: 10.673 | M19: 18.907 | N19: 40.8
B20: UP ROOF FL | C20: D15 | D20: SESMASSX | E20: 0.0097 | F20: -0.0031 | G20: 0 | H20: 0 | I20: 0 | J20: -0.00015 | K20: 1603 | L20: 10.673 | M20: 18.907 | N20: 40.8
... B1133: BASE 2 FL | C1133: D1 | D1133: CORSY1DL MIN | E1133: -0.0004 | F1133: -0.0007 | G1133: 0 | H1133: 0 | I1133: 0 | J1133: -4e-05 | K1133: 1617 | L1133: 9.204 | M1133: 16.757 | N1133: -6

Sheet Center of Mass
B1: Project : | C1: =+DISPLACEMENT!C1 -> BAHRU SARBET MODEL 1-3 q=1
B2: Client : | C2: =+DISPLACEMENT!C2 -> ATO BAHRU
B3: Consultant : | C3: =+DISPLACEMENT!C3 -> 0
B4: Designed by : | C4: =+DISPLACEMENT!C4 -> Sofonias Bezabeh
B6: Center of Mass and Rigidity
B8: Story | C8: Diaphragm | D8: MassX | E8: MassY | F8: XCM | G8: YCM | H8: CumMassX | I8: CumMassY | J8: XCCM | K8: YCCM | L8: XCR | M8: YCR
B9: BASE 2 FL | C9: D1 | D9: 302.8886 | E9: 302.8886 | F9: 9.204 | G9: 16.757 | H9: 302.8886 | I9: 302.8886 | J9: 9.204 | K9: 16.757 | L9: 11.335 | M9: 16.082 | O9: =+J9-L9 -> -2.131 | P9: =+K9-M9 -> 0.675
B10: BASE 1 FL | C10: D2 | D10: 963.2613 | E10: 963.2613 | F10: 7.833 | G10: 16.16 | H10: 963.2613 | I10: 963.2613 | J10: 7.833 | K10: 16.16 | L10: 11.094 | M10: 16.266 | O10: =+J10-L10 -> -3.261 | P10: =+K10-M10 -> -0.106
B11: GROUND FL | C11: D3 | D11: 878.4881 | E11: 878.4881 | F11: 7.539 | G11: 16.069 | H11: 878.4881 | I11: 878.4881 | J11: 7.539 | K11: 16.069 | L11: 10.924 | M11: 16.484 | O11: =+J11-L11 -> -3.385 | P11: =+K11-M11 -> -0.415
B12: 1ST FL | C12: D4 | D12: 805.3196 | E12: 805.3196 | F12: 9.072 | G12: 16.512 | H12: 805.3196 | I12: 805.3196 | J12: 9.072 | K12: 16.512 | L12: 10.305 | M12: 15.466 | O12: =+J12-L12 -> -1.233 | P12: =+K12-M12 -> 1.046
B13: 2ND FL | C13: D5 | D13: 754.8454 | E13: 754.8454 | F13: 9.137 | G13: 16.42 | H13: 754.8454 | I13: 754.8454 | J13: 9.137 | K13: 16.42 | L13: 10.021 | M13: 15.984 | O13: =+J13-L13 -> -0.884 | P13: =+K13-M13 -> 0.436
B14: 3RD FL | C14: D6 | D14: 749.0878 | E14: 749.0878 | F14: 9.151 | G14: 16.419 | H14: 749.0878 | I14: 749.0878 | J14: 9.151 | K14: 16.419 | L14: 10.022 | M14: 16.443 | O14: =+J14-L14 -> -0.871 | P14: =+K14-M14 -> -0.024
B15: 4TH FL | C15: D7 | D15: 743.2589 | E15: 743.2589 | F15: 9.158 | G15: 16.391 | H15: 743.2589 | I15: 743.2589 | J15: 9.158 | K15: 16.391 | L15: 10.054 | M15: 16.752 | O15: =+J15-L15 -> -0.896 | P15: =+K15-M15 -> -0.361
B16: 5TH FL | C16: D8 | D16: 736.6812 | E16: 736.6812 | F16: 9.16 | G16: 16.374 | H16: 736.6812 | I16: 736.6812 | J16: 9.16 | K16: 16.374 | L16: 10.106 | M16: 16.948 | O16: =+J16-L16 -> -0.946 | P16: =+K16-M16 -> -0.574
B17: 6TH FL | C17: D9 | D17: 729.8058 | E17: 729.8058 | F17: 9.156 | G17: 16.375 | H17: 729.8058 | I17: 729.8058 | J17: 9.156 | K17: 16.375 | L17: 10.166 | M17: 17.092 | O17: =+J17-L17 -> -1.01 | P17: =+K17-M17 -> -0.717
B18: 7TH FL | C18: D10 | D18: 724.8256 | E18: 724.8256 | F18: 9.155 | G18: 16.367 | H18: 724.8256 | I18: 724.8256 | J18: 9.155 | K18: 16.367 | L18: 10.226 | M18: 17.196 | O18: =+J18-L18 -> -1.071 | P18: =+K18-M18 -> -0.829
B19: 8TH FL | C19: D11 | D19: 724.6522 | E19: 724.6522 | F19: 9.155 | G19: 16.37 | H19: 724.6522 | I19: 724.6522 | J19: 9.155 | K19: 16.37 | L19: 10.28 | M19: 17.271 | O19: =+J19-L19 -> -1.125 | P19: =+K19-M19 -> -0.901
B20: 9TH FL | C20: D12 | D20: 724.4789 | E20: 724.4789 | F20: 9.155 | G20: 16.373 | H20: 724.4789 | I20: 724.4789 | J20: 9.155 | K20: 16.373 | L20: 10.326 | M20: 17.326 | O20: =+J20-L20 -> -1.171 | P20: =+K20-M20 -> -0.953
... B23: UP ROOF FL | C23: D15 | D23: 95.7139 | E23: 95.7139 | F23: 10.673 | G23: 18.907 | H23: 95.7139 | I23: 95.7139 | J23: 10.673 | K23: 18.907 | L23: 10.87 | M23: 18.265 | O23: =+J23-L23 -> -0.197 | P23: =+K23-M23 -> 0.642

Sheet STOREY SHEARS
B1: ='[1]4.2 Modal Load Participation'!I3 -> Project : | C1: =+DISPLACEMENT!C1 -> BAHRU SARBET MODEL 1-3 q=1
B2: ='[1]4.2 Modal Load Participation'!I4 -> Client : | C2: =+DISPLACEMENT!C2 -> ATO BAHRU
B4: ='[1]4.2 Modal Load Participation'!I5 -> Designed by : | C4: =+[1]DISPLACEMENT!C4 -> Sofonias Bezabeh
B6: Storey Shears
B8: Story | C8: Load | D8: Loc | E8: P | F8: VX | G8: VY | H8: T | I8: MX | J8: MY
B9: UP ROOF FL | C9: EQX | D9: Top | E9: 0 | F9: -38.68 | G9: 0 | H9: 761.29 | I9: 0 | J9: 0
B10: UP ROOF FL | C10: EQX | D10: Bottom | E10: 0 | F10: -38.68 | G10: 0 | H10: 761.289 | I10: 0.011 | J10: -134.595
B11: UP ROOF FL | C11: EQY | D11: Top | E11: 0 | F11: 0 | G11: -38.68 | H11: -421.235 | I11: 0 | J11: 0
B12: UP ROOF FL | C12: EQY | D12: Bottom | E12: 0 | F12: 0 | G12: -38.68 | H12: -421.284 | I12: 133.053 | J12: -0.067
B13: UP ROOF FL | C13: EQXN | D13: Top | E13: 0 | F13: -38.68 | G13: 0 | H13: 701.337 | I13: 0 | J13: 0
B14: UP ROOF FL | C14: EQXN | D14: Bottom | E14: 0 | F14: -38.68 | G14: 0 | H14: 701.335 | I14: 0.133 | J14: -134.531
B15: UP ROOF FL | C15: EQYN | D15: Top | E15: 0 | F15: 0 | G15: -38.68 | H15: -404.41 | I15: 0 | J15: 0
B16: UP ROOF FL | C16: EQYN | D16: Bottom | E16: 0 | F16: 0 | G16: -38.68 | H16: -404.458 | I16: 132.983 | J16: -0.105
B17: UP ROOF FL | C17: UL1 | D17: Top | E17: 0 | F17: -100000 | G17: 0 | H17: 1747200 | I17: 0 | J17: 0
B18: UP ROOF FL | C18: UL1 | D18: Bottom | E18: 0 | F18: -100000 | G18: 0 | H18: 1747198.4 | I18: 5.489 | J18: -342093.06
B19: UP ROOF FL | C19: UL2 | D19: Top | E19: 0 | F19: 0 | G19: -100000 | H19: -1041300 | I19: 0 | J19: 0
B20: UP ROOF FL | C20: UL2 | D20: Bottom | E20: 0 | F20: 0 | G20: -100000 | H20: -1041362 | I20: 341964.63 | J20: -22.135
... B2258: BASE 2 FL | C2258: CORSY1DL MIN | D2258: Bottom | E2258: 107701.09 | F2258: -2478.16 | G2258: -5287.9 | H2258: -80733.359 | I2258: 1657520.3 | J2258: -1035437.9

Sheet Area Assign
A1: Story | B1: Area | C1: AreaType | D1: SectionType | E1: Section | F1: AxisAngle | G1: Diaphragm | H1: StiffMod | I1: Pier | J1: Spandrel | K1: SpandStory | L1: Springs | M1: MassPerArea | N1: MeshOption | O1: UnifLoad | P1: TempLoad | Q1: WindPress | R1: NumCorners | S1: ObjectArea | T1: Perimeter | U1: CentroidX | V1: CentroidY | W1: CentroidZ | X1: PolarInertia
A2: UP ROOF FL | B2: W74 | C2: Wall | D2: Wall | E2: W20 | F2: 0 | I2: P1 | R2: 4 | S2: 7.48 | T2: 11.2 | U2: 11.6 | V2: 16.7 | W2: 39.1 | X2: 10.223 | Y2: =X2+(S2*((U2-INDEX('[1]Center of Mass'!$B$8:$M$105,MATCH(A2,'[1]Center of Mass'!$B$8:$B$105,0),9))^2+(V2-INDEX('[1]Center of Mass'!$B$8:$M$105,MATCH(A2,'[1]Center of Mass'!$B$8:$B$105,0),10))^2)) -> #N/A
A3: UP ROOF FL | B3: W101 | C3: Wall | D3: Wall | E3: W20 | F3: 0 | I3: P1 | R3: 4 | S3: 4.25 | T3: 9.3 | U3: 11.125 | V3: 22 | W3: 39.1 | X3: 4.6476 | Y3: =X3+(S3*((U3-INDEX('[1]Center of Mass'!$B$8:$M$105,MATCH(A3,'[1]Center of Mass'!$B$8:$B$105,0),9))^2+(V3-INDEX('[1]Center of Mass'!$B$8:$M$105,MATCH(A3,'[1]Center of Mass'!$B$8:$B$105,0),10))^2)) -> #N/A
A4: UP ROOF FL | B4: W103 | C4: Wall | D4: Wall | E4: W20 | F4: 0 | I4: P1 | R4: 4 | S4: 3.23 | T4: 8.7 | U4: 12.225 | V4: 22 | W4: 39.1 | X4: 3.3545 | Y4: =X4+(S4*((U4-INDEX('[1]Center of Mass'!$B$8:$M$105,MATCH(A4,'[1]Center of Mass'!$B$8:$B$105,0),9))^2+(V4-INDEX('[1]Center of Mass'!$B$8:$M$105,MATCH(A4,'[1]Center of Mass'!$B$8:$B$105,0),10))^2)) -> #N/A
A5: ROOF FL | B5: W74 | C5: Wall | D5: Wall | E5: W20 | F5: 0 | I5: P1 | R5: 4 | S5: 7.48 | T5: 11.2 | U5: 11.6 | V5: 16.7 | W5: 35.7 | X5: 10.223 | Y5: =X5+(S5*((U5-INDEX('[1]Center of Mass'!$B$8:$M$105,MATCH(A5,'[1]Center of Mass'!$B$8:$B$105,0),9))^2+(V5-INDEX('[1]Center of Mass'!$B$8:$M$105,MATCH(A5,'[1]Center of Mass'!$B$8:$B$105,0),10))^2)) -> 894.65162
A6: ROOF FL | B6: W101 | C6: Wall | D6: Wall | E6: W20 | F6: 0 | I6: P1 | R6: 4 | S6: 4.25 | T6: 9.3 | U6: 11.125 | V6: 22 | W6: 35.7 | X6: 4.6476 | Y6: =X6+(S6*((U6-INDEX('[1]Center of Mass'!$B$8:$M$105,MATCH(A6,'[1]Center of Mass'!$B$8:$B$105,0),9))^2+(V6-INDEX('[1]Center of Mass'!$B$8:$M$105,MATCH(A6,'[1]Center of Mass'!$B$8:$B$105,0),10))^2)) -> 871.23427
A7: ROOF FL | B7: W103 | C7: Wall | D7: Wall | E7: W20 | F7: 0 | I7: P1 | R7: 4 | S7: 3.23 | T7: 8.7 | U7: 12.225 | V7: 22 | W7: 35.7 | X7: 3.3545 | Y7: =X7+(S7*((U7-INDEX('[1]Center of Mass'!$B$8:$M$105,MATCH(A7,'[1]Center of Mass'!$B$8:$B$105,0),9))^2+(V7-INDEX('[1]Center of Mass'!$B$8:$M$105,MATCH(A7,'[1]Center of Mass'!$B$8:$B$105,0),10))^2)) -> 592.22919
A8: ROOF FL | B8: W161 | C8: Wall | D8: Wall | E8: W20 | F8: 0 | I8: P1 | R8: 4 | S8: 3.23 | T8: 8.7 | U8: 11.275 | V8: 30.6 | W8: 35.7 | X8: 3.3545 | Y8: =X8+(S8*((U8-INDEX('[1]Center of Mass'!$B$8:$M$105,MATCH(A8,'[1]Center of Mass'!$B$8:$B$105,0),9))^2+(V8-INDEX('[1]Center of Mass'!$B$8:$M$105,MATCH(A8,'[1]Center of Mass'!$B$8:$B$105,0),10))^2)) -> 1436.6642
A9: ROOF FL | B9: W162 | C9: Wall | D9: Wall | E9: W20 | F9: 0 | I9: P1 | R9: 4 | S9: 3.23 | T9: 8.7 | U9: 12.225 | V9: 30.6 | W9: 35.7 | X9: 3.3545 | Y9: =X9+(S9*((U9-INDEX('[1]Center of Mass'!$B$8:$M$105,MATCH(A9,'[1]Center of Mass'!$B$8:$B$105,0),9))^2+(V9-INDEX('[1]Center of Mass'!$B$8:$M$105,MATCH(A9,'[1]Center of Mass'!$B$8:$B$105,0),10))^2)) -> 1376.9021
A10: ROOF FL | B10: W163 | C10: Wall | D10: Wall | E10: W30 | F10: 0 | I10: P1 | R10: 4 | S10: 4.25 | T10: 9.3 | U10: 0.625 | V10: 0 | W10: 35.7 | X10: 4.6476 | Y10: =X10+(S10*((U10-INDEX('[1]Center of Mass'!$B$8:$M$105,MATCH(A10,'[1]Center of Mass'!$B$8:$B$105,0),9))^2+(V10-INDEX('[1]Center of Mass'!$B$8:$M$105,MATCH(A10,'[1]Center of Mass'!$B$8:$B$105,0),10))^2)) -> 2484.6065
A11: ROOF FL | B11: W164 | C11: Wall | D11: Wall | E11: W30 | F11: 0 | I11: P1 | R11: 4 | S11: 3.485 | T11: 8.85 | U11: 1.763 | V11: 0 | W11: 35.7 | X11: 3.6623 | Y11: =X11+(S11*((U11-INDEX('[1]Center of Mass'!$B$8:$M$105,MATCH(A11,'[1]Center of Mass'!$B$8:$B$105,0),9))^2+(V11-INDEX('[1]Center of Mass'!$B$8:$M$105,MATCH(A11,'[1]Center of Mass'!$B$8:$B$105,0),10))^2)) -> 1876.2594
A12: 10TH FL | B12: W74 | C12: Wall | D12: Wall | E12: W20 | F12: 0 | I12: P1 | R12: 4 | S12: 7.48 | T12: 11.2 | U12: 11.6 | V12: 16.7 | W12: 32.3 | X12: 10.223 | Y12: =X12+(S12*((U12-INDEX('[1]Center of Mass'!$B$8:$M$105,MATCH(A12,'[1]Center of Mass'!$B$8:$B$105,0),9))^2+(V12-INDEX('[1]Center of Mass'!$B$8:$M$105,MATCH(A12,'[1]Center of Mass'!$B$8:$B$105,0),10))^2)) -> 828.43247
A13: 10TH FL | B13: W101 | C13: Wall | D13: Wall | E13: W20 | F13: 0 | I13: P1 | R13: 4 | S13: 4.25 | T13: 9.3 | U13: 11.125 | V13: 22 | W13: 32.3 | X13: 4.6476 | Y13: =X13+(S13*((U13-INDEX('[1]Center of Mass'!$B$8:$M$105,MATCH(A13,'[1]Center of Mass'!$B$8:$B$105,0),9))^2+(V13-INDEX('[1]Center of Mass'!$B$8:$M$105,MATCH(A13,'[1]Center of Mass'!$B$8:$B$105,0),10))^2)) -> 781.54343
... A83: 1ST FL | B83: W164 | C83: Wall | D83: Wall | E83: W40 | F83: 0 | I83: P1 | R83: 4 | S83: 3.485 | T83: 8.85 | U83: 1.763 | V83: 0 | W83: 1.7 | X83: 3.6623 | Y83: =X83+(S83*((U83-INDEX('[1]Center of Mass'!$B$8:$M$105,MATCH(A83,'[1]Center of Mass'!$B$8:$B$105,0),9))^2+(V83-INDEX('[1]Center of Mass'!$B$8:$M$105,MATCH(A83,'[1]Center of Mass'!$B$8:$B$105,0),10))^2)) -> 1893.5097
A84: GROUND FL | B84: W1 | C84: Wall | D84: Wall | E84: RW30 | F84: 0 | R84: 4 | S84: 3.75 | T84: 8.5 | U84: 0.625 | V84: -1.1 | W84: -1.5 | X84: 3.3008 | Y84: =X84+(S84*((U84-INDEX('[1]Center of Mass'!$B$8:$M$105,MATCH(A84,'[1]Center of Mass'!$B$8:$B$105,0),9))^2+(V84-INDEX('[1]Center of Mass'!$B$8:$M$105,MATCH(A84,'[1]Center of Mass'!$B$8:$B$105,0),10))^2)) -> 2241.3971
A85: GROUND FL | B85: W2 | C85: Wall | D85: Wall | E85: RW30 | F85: 0 | R85: 4 | S85: 3.075 | T85: 8.05 | U85: 1.763 | V85: -1.1 | W85: -1.5 | X85: 2.5755 | Y85: =X85+(S85*((U85-INDEX('[1]Center of Mass'!$B$8:$M$105,MATCH(A85,'[1]Center of Mass'!$B$8:$B$105,0),9))^2+(V85-INDEX('[1]Center of Mass'!$B$8:$M$105,MATCH(A85,'[1]Center of Mass'!$B$8:$B$105,0),10))^2)) -> 1694.5091
A86: GROUND FL | B86: W3 | C86: Wall | D86: Wall | E86: RW30 | F86: 0 | R86: 4 | S86: 3.075 | T86: 8.05 | U86: 2.788 | V86: -1.1 | W86: -1.5 | X86: 2.5755 | Y86: =X86+(S86*((U86-INDEX('[1]Center of Mass'!$B$8:$M$105,MATCH(A86,'[1]Center of Mass'!$B$8:$B$105,0),9))^2+(V86-INDEX('[1]Center of Mass'!$B$8:$M$105,MATCH(A86,'[1]Center of Mass'!$B$8:$B$105,0),10))^2)) -> 1572.251
A87: GROUND FL | B87: W4 | C87: Wall | D87: Wall | E87: RW30 | F87: 0 | R87: 4 | S87: 3.9 | T87: 8.6 | U87: 3.95 | V87: -1.1 | W87: -1.5 | X87: 3.4743 | Y87: =X87+(S87*((U87-INDEX('[1]Center of Mass'!$B$8:$M$105,MATCH(A87,'[1]Center of Mass'!$B$8:$B$105,0),9))^2+(V87-INDEX('[1]Center of Mass'!$B$8:$M$105,MATCH(A87,'[1]Center of Mass'!$B$8:$B$105,0),10))^2)) -> 1828.4093
A88: GROUND FL | B88: W5 | C88: Wall | D88: Wall | E88: RW30 | F88: 0 | R88: 4 | S88: 4.2 | T88: 8.8 | U88: 5.3 | V88: -1.1 | W88: -1.5 | X88: 3.836 | Y88: =X88+(S88*((U88-INDEX('[1]Center of Mass'!$B$8:$M$105,MATCH(A88,'[1]Center of Mass'!$B$8:$B$105,0),9))^2+(V88-INDEX('[1]Center of Mass'!$B$8:$M$105,MATCH(A88,'[1]Center of Mass'!$B$8:$B$105,0),10))^2)) -> 1775.8603
A89: GROUND FL | B89: W6 | C89: Wall | D89: Wall | E89: RW30 | F89: 0 | R89: 4 | S89: 3.6 | T89: 8.4 | U89: 6.6 | V89: -1.1 | W89: -1.5 | X89: 3.132 | Y89: =X89+(S89*((U89-INDEX('[1]Center of Mass'!$B$8:$M$105,MATCH(A89,'[1]Center of Mass'!$B$8:$B$105,0),9))^2+(V89-INDEX('[1]Center of Mass'!$B$8:$M$105,MATCH(A89,'[1]Center of Mass'!$B$8:$B$105,0),10))^2)) -> 1374.8708
A90: GROUND FL | B90: W7 | C90: Wall | D90: Wall | E90: RW30 | F90: 0 | R90: 4 | S90: 3.45 | T90: 8.3 | U90: 7.775 | V90: -1.1 | W90: -1.5 | X90: 2.9677 | Y90: =X90+(S90*((U90-INDEX('[1]Center of Mass'!$B$8:$M$105,MATCH(A90,'[1]Center of Mass'!$B$8:$B$105,0),9))^2+(V90-INDEX('[1]Center of Mass'!$B$8:$M$105,MATCH(A90,'[1]Center of Mass'!$B$8:$B$105,0),10))^2)) -> 1200.1338
A91: GROUND FL | B91: W8 | C91: Wall | D91: Wall | E91: RW30 | F91: 0 | R91: 4 | S91: 3.45 | T91: 8.3 | U91: 8.925 | V91: -1.1 | W91: -1.5 | X91: 2.9677 | Y91: =X91+(S91*((U91-INDEX('[1]Center of Mass'!$B$8:$M$105,MATCH(A91,'[1]Center of Mass'!$B$8:$B$105,0),9))^2+(V91-INDEX('[1]Center of Mass'!$B$8:$M$105,MATCH(A91,'[1]Center of Mass'!$B$8:$B$105,0),10))^2)) -> 1094.4396
A92: GROUND FL | B92: W9 | C92: Wall | D92: Wall | E92: RW30 | F92: 0 | R92: 4 | S92: 4.7878 | T92: 9.192 | U92: 10.298 | V92: -1.1 | W92: -1.5 | X92: 4.607 | Y92: =X92+(S92*((U92-INDEX('[1]Center of Mass'!$B$8:$M$105,MATCH(A92,'[1]Center of Mass'!$B$8:$B$105,0),9))^2+(V92-INDEX('[1]Center of Mass'!$B$8:$M$105,MATCH(A92,'[1]Center of Mass'!$B$8:$B$105,0),10))^2)) -> 1360.7802
A93: GROUND FL | B93: W10 | C93: Wall | D93: Wall | E93: RW30 | F93: 0 | R93: 4 | S93: 4.8122 | T93: 9.208 | U93: 11.898 | V93: -1.1 | W93: -1.5 | X93: 4.641 | Y93: =X93+(S93*((U93-INDEX('[1]Center of Mass'!$B$8:$M$105,MATCH(A93,'[1]Center of Mass'!$B$8:$B$105,0),9))^2+(V93-INDEX('[1]Center of Mass'!$B$8:$M$105,MATCH(A93,'[1]Center of Mass'!$B$8:$B$105,0),10))^2)) -> 1204.927
A94: GROUND FL | B94: W11 | C94: Wall | D94: Wall | E94: RW30 | F94: 0 | R94: 4 | S94: 3.3095 | T94: 8.206 | U94: 13.252 | V94: -1.1 | W94: -1.5 | X94: 2.8178 | Y94: =X94+(S94*((U94-INDEX('[1]Center of Mass'!$B$8:$M$105,MATCH(A94,'[1]Center of Mass'!$B$8:$B$105,0),9))^2+(V94-INDEX('[1]Center of Mass'!$B$8:$M$105,MATCH(A94,'[1]Center of Mass'!$B$8:$B$105,0),10))^2)) -> 746.7814
A95: GROUND FL | B95: W12 | C95: Wall | D95: Wall | E95: RW30 | F95: 0 | R95: 4 | S95: 3.3095 | T95: 8.206 | U95: 14.355 | V95: -1.1 | W95: -1.5 | X95: 2.8178 | Y95: =X95+(S95*((U95-INDEX('[1]Center of Mass'!$B$8:$M$105,MATCH(A95,'[1]Center of Mass'!$B$8:$B$105,0),9))^2+(V95-INDEX('[1]Center of Mass'!$B$8:$M$105,MATCH(A95,'[1]Center of Mass'!$B$8:$B$105,0),10))^2)) -> 689.34999
... A134: GROUND FL | B134: W67 | C134: Wall | D134: Wall | E134: RW30 | F134: 0 | R134: 4 | S134: 3.6098 | T134: 8.407 | U134: -0.724 | V134: 16.1 | W134: -1.5 | X134: 3.1429 | Y134: =X134+(S134*((U134-INDEX('[1]Center of Mass'!$B$8:$M$105,MATCH(A134,'[1]Center of Mass'!$B$8:$B$105,0),9))^2+(V134-INDEX('[1]Center of Mass'!$B$8:$M$105,MATCH(A134,'[1]Center of Mass'!$B$8:$B$105,0),10))^2)) -> 1896.3534
A135: GROUND FL | B135: W72 | C135: Wall | D135: Wall | E135: W20 | F135: 0 | I135: P1 | R135: 4 | S135: 1.035 | T135: 4.65 | U135: 10.8 | V135: 16.7 | W135: -2.138 | X135: 0.2877 | Y135: =X135+(S135*((U135-INDEX('[1]Center of Mass'!$B$8:$M$105,MATCH(A135,'[1]Center of Mass'!$B$8:$B$105,0),9))^2+(V135-INDEX('[1]Center of Mass'!$B$8:$M$105,MATCH(A135,'[1]Center of Mass'!$B$8:$B$105,0),10))^2)) -> 152.6825
A136: GROUND FL | B136: W73 | C136: Wall | D136: Wall | E136: W20 | F136: 0 | I136: P1 | R136: 4 | S136: 0.765 | T136: 3.75 | U136: 10.8 | V136: 16.7 | W136: -0.638 | X136: 0.12658 | Y136: =X136+(S136*((U136-INDEX('[1]Center of Mass'!$B$8:$M$105,MATCH(A136,'[1]Center of Mass'!$B$8:$B$105,0),9))^2+(V136-INDEX('[1]Center of Mass'!$B$8:$M$105,MATCH(A136,'[1]Center of Mass'!$B$8:$B$105,0),10))^2)) -> 112.76621
A137: GROUND FL | B137: W76 | C137: Wall | D137: Wall | E137: W20 | F137: 0 | I137: P1 | R137: 4 | S137: 2.76 | T137: 6.65 | U137: 11.9 | V137: 16.7 | W137: -2.138 | X137: 1.2732 | Y137: =X137+(S137*((U137-INDEX('[1]Center of Mass'!$B$8:$M$105,MATCH(A137,'[1]Center of Mass'!$B$8:$B$105,0),9))^2+(V137-INDEX('[1]Center of Mass'!$B$8:$M$105,MATCH(A137,'[1]Center of Mass'!$B$8:$B$105,0),10))^2)) -> 344.99628
A138: GROUND FL | B138: W77 | C138: Wall | D138: Wall | E138: W20 | F138: 0 | I138: P1 | R138: 4 | S138: 2.04 | T138: 5.75 | U138: 11.9 | V138: 16.7 | W138: -0.638 | X138: 0.71156 | Y138: =X138+(S138*((U138-INDEX('[1]Center of Mass'!$B$8:$M$105,MATCH(A138,'[1]Center of Mass'!$B$8:$B$105,0),9))^2+(V138-INDEX('[1]Center of Mass'!$B$8:$M$105,MATCH(A138,'[1]Center of Mass'!$B$8:$B$105,0),10))^2)) -> 254.76775
A139: GROUND FL | B139: W78 | C139: Wall | D139: Wall | E139: RW30 | F139: 0 | R139: 4 | S139: 1.6113 | T139: 5.109 | U139: 18.4 | V139: 16.033 | W139: -0.587 | X139: 0.44047 | Y139: =X139+(S139*((U139-INDEX('[1]Center of Mass'!$B$8:$M$105,MATCH(A139,'[1]Center of Mass'!$B$8:$B$105,0),9))^2+(V139-INDEX('[1]Center of Mass'!$B$8:$M$105,MATCH(A139,'[1]Center of Mass'!$B$8:$B$105,0),10))^2)) -> 53.658448
A140: GROUND FL | B140: W79 | C140: Wall | D140: Wall | E140: RW30 | F140: 0 | R140: 4 | S140: 3.7603 | T140: 8.507 | U140: -0.814 | V140: 17.325 | W140: -1.5 | X140: 3.3125 | Y140: =X140+(S140*((U140-INDEX('[1]Center of Mass'!$B$8:$M$105,MATCH(A140,'[1]Center of Mass'!$B$8:$B$105,0),9))^2+(V140-INDEX('[1]Center of Mass'!$B$8:$M$105,MATCH(A140,'[1]Center of Mass'!$B$8:$B$105,0),10))^2)) -> 2040.4422
A141: GROUND FL | B141: W82 | C141: Wall | D141: Wall | E141: RW30 | F141: 0 | R141: 4 | S141: 4.0358 | T141: 8.351 | U141: 18.784 | V141: 17.899 | W141: -2.227 | X141: 3.1243 | Y141: =X141+(S141*((U141-INDEX('[1]Center of Mass'!$B$8:$M$105,MATCH(A141,'[1]Center of Mass'!$B$8:$B$105,0),9))^2+(V141-INDEX('[1]Center of Mass'!$B$8:$M$105,MATCH(A141,'[1]Center of Mass'!$B$8:$B$105,0),10))^2)) -> 212.11199
A142: GROUND FL | B142: W83 | C142: Wall | D142: Wall | E142: RW30 | F142: 0 | R142: 4 | S142: 3.7603 | T142: 8.507 | U142: -0.907 | V142: 18.575 | W142: -1.5 | X142: 3.3125 | Y142: =X142+(S142*((U142-INDEX('[1]Center of Mass'!$B$8:$M$105,MATCH(A142,'[1]Center of Mass'!$B$8:$B$105,0),9))^2+(V142-INDEX('[1]Center of Mass'!$B$8:$M$105,MATCH(A142,'[1]Center of Mass'!$B$8:$B$105,0),10))^2)) -> 2118.6495
A143: GROUND FL | B143: W90 | C143: Wall | D143: Wall | E143: RW30 | F143: 0 | R143: 4 | S143: 3.8389 | T143: 8.201 | U143: 18.817 | V143: 18.003 | W143: -0.735 | X143: 2.8988 | Y143: =X143+(S143*((U143-INDEX('[1]Center of Mass'!$B$8:$M$105,MATCH(A143,'[1]Center of Mass'!$B$8:$B$105,0),9))^2+(V143-INDEX('[1]Center of Mass'!$B$8:$M$105,MATCH(A143,'[1]Center of Mass'!$B$8:$B$105,0),10))^2)) -> 206.26846
A144: GROUND FL | B144: W91 | C144: Wall | D144: Wall | E144: RW30 | F144: 0 | R144: 4 | S144: 2.8077 | T144: 7.872 | U144: -0.988 | V144: 19.667 | W144: -1.5 | X144: 2.3107 | Y144: =X144+(S144*((U144-INDEX('[1]Center of Mass'!$B$8:$M$105,MATCH(A144,'[1]Center of Mass'!$B$8:$B$105,0),9))^2+(V144-INDEX('[1]Center of Mass'!$B$8:$M$105,MATCH(A144,'[1]Center of Mass'!$B$8:$B$105,0),10))^2)) -> 1639.9707
A145: GROUND FL | B145: W92 | C145: Wall | D145: Wall | E145: RW30 | F145: 0 | R145: 4 | S145: 1.5703 | T145: 5.026 | U145: 19.2 | V145: 19.809 | W145: -2.371 | X145: 0.4129 | Y145: =X145+(S145*((U145-INDEX('[1]Center of Mass'!$B$8:$M$105,MATCH(A145,'[1]Center of Mass'!$B$8:$B$105,0),9))^2+(V145-INDEX('[1]Center of Mass'!$B$8:$M$105,MATCH(A145,'[1]Center of Mass'!$B$8:$B$105,0),10))^2)) -> 123.50071
A146: GROUND FL | B146: W93 | C146: Wall | D146: Wall | E146: RW30 | F146: 0 | R146: 4 | S146: 2.1797 | T146: 6.001 | U146: 19.2 | V146: 19.836 | W146: -0.873 | X146: 0.83904 | Y146: =X146+(S146*((U146-INDEX('[1]Center of Mass'!$B$8:$M$105,MATCH(A146,'[1]Center of Mass'!$B$8:$B$105,0),9))^2+(V146-INDEX('[1]Center of Mass'!$B$8:$M$105,MATCH(A146,'[1]Center of Mass'!$B$8:$B$105,0),10))^2)) -> 172.69692
A147: GROUND FL | B147: W94 | C147: Wall | D147: Wall | E147: RW30 | F147: 0 | R147: 4 | S147: 2.8077 | T147: 7.872 | U147: -1.057 | V147: 20.6 | W147: -1.5 | X147: 2.3107 | Y147: =X147+(S147*((U147-INDEX('[1]Center of Mass'!$B$8:$M$105,MATCH(A147,'[1]Center of Mass'!$B$8:$B$105,0),9))^2+(V147-INDEX('[1]Center of Mass'!$B$8:$M$105,MATCH(A147,'[1]Center of Mass'!$B$8:$B$105,0),10))^2)) -> 1695.0067
...

Sheet 4.2 Modal Load Participation
B1: 4.2. Fundamental Period and Modal mass participation
I3: Project : | K3: ='STOREY SHEARS'!C1 -> BAHRU SARBET MODEL 1-3 q=1
I4: Client : | K4: ='STOREY SHEARS'!C2 -> ATO BAHRU
I5: Designed by : | K5: ='STOREY SHEARS'!C4 -> Sofonias Bezabeh
B7: The First mode of vibration or fundamental period of a building will be = | I7: =MAX(F9:F10) -> 2.807803 | J7: sec
E9: T1x= | F9: =+INDEX(B15:O44,MATCH(J9,D15:D44,0),2) -> 2.568473 | G9: with a participated % mass of = | J9: =+MAX(D15:D44) -> 49.8674 | K9: %
E10: T1y= | F10: =+INDEX(B15:O44,MATCH(J10,E15:E44,0),2) -> 2.807803 | G10: with a participated % mass of = | J10: =+MAX(E15:E44) -> 55.8171 | K10: %
B12: Modal Load Participation
B14: Mode | C14: Period | D14: UX | E14: UY | F14: UZ | G14: SumUX | H14: SumUY | I14: SumUZ | J14: RX | K14: RY | L14: RZ | M14: SumRX | N14: SumRY | O14: SumRZ
B15: 1 | C15: 2.807803 | D15: 0.5449 | E15: 55.8171 | F15: 0 | G15: 0.5449 | H15: 55.8171 | I15: 0 | J15: 89.5792 | K15: 0.7501 | L15: 3.2477 | M15: 89.5792 | N15: 0.7501 | O15: 3.2477
B16: 2 | C16: 2.568473 | D16: 49.8674 | E16: 2.0086 | F16: 0 | G16: 50.4124 | H16: 57.8257 | I16: 0 | J16: 3.1766 | K16: 68.4918 | L16: 6.4834 | M16: 92.7558 | N16: 69.2419 | O16: 9.7312
B17: 3 | C17: 2.327159 | D17: 8.1845 | E17: 2.4267 | F17: 0 | G17: 58.5968 | H17: 60.2524 | I17: 0 | J17: 3.845 | K17: 10.9942 | L17: 46.6802 | M17: 96.6008 | N17: 80.236 | O17: 56.4113
B18: 4 | C18: 0.921909 | D18: 0.0183 | E18: 8.7915 | F18: 0 | G18: 58.6151 | H18: 69.0438 | I18: 0 | J18: 0.4744 | K18: 0.0028 | L18: 0.2999 | M18: 97.0751 | N18: 80.2388 | O18: 56.7112
B19: 5 | C19: 0.786264 | D19: 8.7658 | E19: 0.1039 | F19: 0 | G19: 67.3809 | H19: 69.1477 | I19: 0 | J19: 0.0065 | K19: 3.2884 | L19: 1.63 | M19: 97.0817 | N19: 83.5272 | O19: 58.3411
B20: 6 | C20: 0.72517 | D20: 1.7785 | E20: 0.1172 | F20: 0 | G20: 69.1594 | H20: 69.2649 | I20: 0 | J20: 0.0024 | K20: 0.8657 | L20: 8.1384 | M20: 97.0841 | N20: 84.3929 | O20: 66.4795
B21: 7 | C21: 0.522001 | D21: 0.0035 | E21: 3.4752 | F21: 0 | G21: 69.1629 | H21: 72.7401 | I21: 0 | J21: 0.9295 | K21: 0.0001 | L21: 0.0694 | M21: 98.0136 | N21: 84.393 | O21: 66.549
B22: 8 | C22: 0.401889 | D22: 5.061 | E22: 0.0086 | F22: 0 | G22: 74.2239 | H22: 72.7487 | I22: 0 | J22: 0.001 | K22: 0.5654 | L22: 0.0897 | M22: 98.0146 | N22: 84.9584 | O22: 66.6387
B23: 9 | C23: 0.379827 | D23: 0.0328 | E23: 0.0169 | F23: 0 | G23: 74.2567 | H23: 72.7655 | I23: 0 | J23: 0.0067 | K23: 0.0056 | L23: 4.8036 | M23: 98.0214 | N23: 84.964 | O23: 71.4423
B24: 10 | C24: 0.357443 | D24: 0.0052 | E24: 2.1658 | F24: 0 | G24: 74.2619 | H24: 74.9314 | I24: 0 | J24: 0.1784 | K24: 0.0003 | L24: 0.0313 | M24: 98.1998 | N24: 84.9643 | O24: 71.4736
B25: 11 | C25: 0.267528 | D25: 0.0127 | E25: 1.498 | F25: 0 | G25: 74.2746 | H25: 76.4293 | I25: 0 | J25: 0.2417 | K25: 0.0064 | L25: 0.0627 | M25: 98.4415 | N25: 84.9707 | O25: 71.5363
B26: 12 | C26: 0.252397 | D26: 4.0177 | E26: 0.0036 | F26: 0 | G26: 78.2923 | H26: 76.4329 | I26: 0 | J26: 0.0007 | K26: 1.5169 | L26: 0.2923 | M26: 98.4422 | N26: 86.4876 | O26: 71.8286
... B64: 50 | C64: 0.02853 | D64: 0.0031 | E64: 0.0185 | F64: 0 | G64: 99.8913 | H64: 99.9002 | I64: 0 | J64: 0.0151 | K64: 0.022 | L64: 0.0008 | M64: 99.9403 | N64: 99.7042 | O64: 99.9645

Sheet 2.4. Load and Load Factor
A1: 2.4 | B1: Loading | E1: Project : | G1: =+DISPLACEMENT!C1 -> BAHRU SARBET MODEL 1-3 q=1
E2: Client : | G2: =+DISPLACEMENT!C2 -> ATO BAHRU
E3: Designed by : | G3: =+DISPLACEMENT!C4 -> Sofonias Bezabeh
B4: 2.4.1. Applied Loads
B5: The types of loads acting on structures for buildings and other structures can be broadly classified as vertical loads, horizontal loads and longitudinal loads. The vertical loads consist of dead load, live load and impact load. The horizontal loads comprise of wind load and earthquake load. The longitudinal loads i.e. tractive and braking forces are considered in special case of design of bridges, gantry girders etc.
B6: Vertical Loads | M6: Category A | O6: 2
B7: Permanent (Dead) Load – Dead load is primarily due to self-weight of structural members, permanent partition walls, fixed permanent equipment’s and weight of different materials.
B8: · | C8: Self-weight- self weight of every members of the structures calculated by ETABS ultimate 2017 based on a provided data. For reinforced concrete structure 25kN/m3 nominal density is applied based on ES EN 1991-1-1:2001 Annex A. | M8: Category B | O8: 2
B9: · | C9: Imposed Dead loads All imposed Dead loads are accounted based on Architectural drawing | M9: Category C1 | O9: 3
M10: Category C2 | O10: 4
B11: Live (occupational) load | M11: Category C3 | O11: 5
B12: Live loads are either movable or moving loads without any acceleration or impact. These loads are assumed to be produced by the intended use or occupancy of the building. The different live load categories are used in the model as per the architectural plan the requirement of the ES EN 1991-1-1:2015. | M12: Category C4 | O12: 5
M13: Category C5 | O13: 7.5
C14: Live load Correction Factor : The inertial effects of the design seismic action shall be evaluated by taking into account thepresence of the masses associated with all gravity loads appearing in the following combination of | M14: Category D1 | O14: 4
M15: Category D2 | O15: 5
D16: yE,i is the combination coefficient for variable action i | M16: Category E1 | O16: 7.5
C17: The combination coefficients ψEi introduced in Design Seismic Forces computed as follow
M18: Category E2 | O18: 7.5
D19: According to EBCS EN 1998-1-1:2015 section 4.2.4 | M19: Catergory G | O19: 5
C21: Basement Floors and Car Parkings, Category F
D22: Self-Weight | E22: Included by Analysis Software (ETABS 9.74 & ETABS Ultimate 2017)
C23: Dead load | E23: Thickness | G23: Distributed load
D24: Plastering load | E24: 15 | F24: mm | G24: =22*E24/1000 -> 0.33 | H24: kN/m2
D25: Cement Screed Load | E25: 30 | F25: mm | G25: =E25*25/1000 -> 0.75 | H25: kN/m2
D26: Partition wall load including Plastering | E26: 15 | F26: mm | G26: 0.61 | H26: kN/m2
D27: Floor Finish | E27: 30 | F27: mm | G27: =27*E27/1000 -> 0.81 | H27: kN/m2
D28: Total Dead Load (kN/m2) | G28: =G24+G25+G26+G27 -> 2.5 | H28: kN/m2
C30: Live Load | D30: Live Load Category | E30: Category D1
D31: Cobination coefficient for variable Action (yEi) | E31: y | F31: 1 | G31: =+F31*F32 -> 0.6
E32: y2i | F32: 0.6
D33: Live Load (kN/m2) | E33: 5
D34: Applied Factored Live load (kN/m2) | E34: =E33*G31 -> 3
C36: Ground floor, Shopping Floor, Category D
D37: Self-Weight | E37: Included by Analysis Software (ETABS 9.74 & ETABS Ultimate 2017)
C38: Dead load | E38: Thickness | G38: Distributed load
D39: Plastering load | E39: 20 | F39: mm | G39: =22*E39/1000 -> 0.44 | H39: kN/m2
D40: Cement Screed Load | E40: 30 | F40: mm | G40: =E40*25/1000 -> 0.75 | H40: kN/m2
D41: Partition wall load including Plastering | E41: 15 | F41: mm | G41: 1.5 | H41: kN/m2
D42: Floor Finish | E42: 30 | F42: mm | G42: =27*E42/1000 -> 0.81 | H42: kN/m2
D43: Total Dead Load (kN/m2) | G43: =G39+G40+G41+G42 -> 3.5 | H43: kN/m2
...

Sheet 2.5.Concrete Cover
B2: 2.5 Concrete cover evaluation | G2: Project : | I2: =+DISPLACEMENT!C1 -> BAHRU SARBET MODEL 1-3 q=1
G3: Client : | I3: =+DISPLACEMENT!C2 -> ATO BAHRU
G4: Designed by : | I4: =+DISPLACEMENT!C4 -> Sofonias Bezabeh
C6: The required protection of the structure shall be established by considering its intended use, desing working life, maintenance programme and actions. one of the main way of creating protection for structure is through concrete cover. Concrete cover is the distance between the surface of the reinforcement closest to the nearest concrete surface including links and stirrps and surface reinforcement where relevant and the nearest concrete Surface. The nominal cover shall be specified on the drawings it is defined as a minimum cover , Cmin plus an allowance in design for deviation Cdev according to section 4.4.1 of ES EN 1992-1-1:2015
D8: Cnom=C min + ΔCdev
D9: Cnom = | E9: Nominal Concrete Cover
D10: Cmin = | E10: Minimum Concrete Cover
D11: ΔCdev = | E11: Cover for Allowance of deviation
B13: > | C13: Minimum Cover (Cmin)
C14: Minimum concrete cover, Cmin shall be provided in order to ensure: | T14: Separated
D15: » | E15: Safe Transmission of bond forces (Cmin,b) | T15: Bundled
D16: » | E16: the protection of the steel against corrosion
D17: » | E17: adequate fire resistance | T17: Less than 32mm
T18: Greater than 32mm
D25: cmin,b minimum cover due to bond requirement, see 4.4.1.2 (3) ES EN 2015
D26: cmin,dur minimum cover due to environmental conditions, see 4.4.1.2 (5)
D27: ∆cdur,γ additive safety element, see 4.4.1.2 (6) ES EN 2015
D28: ∆cdur,st reduction of minimum cover for use of stainless steel
D29: ∆cdur,add reduction of minimum cover for use of additional protection
C32: Minimum Cover due to Bond requirment
C33: In order to Transmit bond forces safely and to ensure adequate compactionof the concrete, the minimum cover should not be less than Cmin,b. it depends on Rebar arregment and aggregate size
C34: Rebar Arregment | E34: Separated
C35: Aggregate Size | E35: Less than 32mm
D37: Type | E37: Cmin,b
C38: √ | D38: Slab | E38: =IF(AND($E$34="Separated ",$E$35="Less than 32mm"),"12",IF(AND($E$34="Separated ",$E$35="Greater than 32mm"),"17","Check sec 8.9.1 of ES EN 2015")) -> 12 | F38: mm | M38: =E38 -> 12
C39: √ | D39: Beam | E39: =IF(AND($E$34="Separated ",$E$35="Less than 32mm"),"20",IF(AND($E$34="Separated ",$E$35="Greater than 32mm"),"25","Check sec 8.9.1 of ES EN 2015")) -> 20 | F39: mm | M39: =E39 -> 20
C40: √ | D40: Column | E40: =IF(AND($E$34="Separated ",$E$35="Less than 32mm"),"20",IF(AND($E$34="Separated ",$E$35="Greater than 32mm"),"25","Check sec 8.9.1 of ES EN 2015")) -> 20 | F40: mm | M40: =E40 -> 20
C41: √ | D41: Footing | E41: =IF(AND($E$34="Separated ",$E$35="Less than 32mm"),"20",IF(AND($E$34="Separated ",$E$35="Greater than 32mm"),"25","Check sec 8.9.1 of ES EN 2015")) -> 20 | F41: mm | M41: =E41 -> 20
C43: Minimum Cover due to Enviromental Condition (C min,dur)
C44: The minimum cover values for reinforcemetn and prestressing tendns in normal weight concrete taking account of the exposure classed and the structural classed is given by C min,dur it is depends on Exposure class of Concrete and Structural Classes
C46: Exposure class for Corrusion indused by Carbonation
C55: For Super-structure XC1 is advicable
C56: For Sub-structure use class XC2
C73: For this building the structural Class will be S5
D83: Therefore for XC1 and S5 Cover will be | G83: 20 | H83: mm
D84: Therefore for XC2 and S5 Cover will be | G84: 30 | H84: mm
C86: » | D86: Adviced value of ∆cdur,γ additive safety element is 0mm
C87: » | D87: The Recommended value for ∆cdur,st reduction of minimum cover for use of
D88: stainless steel is 0mm
C89: » | D89: ∆cdur,add reduction of minimum cover for use of additional protection is also 0mm
...

Sheet 3.2 Structual Regularity
A2: 3.2 | B2: Structural Regularity | G2: Project : | H2: ='4.3 Geometric Imperfetion'!I1 -> BAHRU SARBET MODEL 1-3 q=1
G3: Client : | H3: ='4.3 Geometric Imperfetion'!I2 -> ATO BAHRU
A4: 3.2.1. Regularity in plan | G4: Designed by : | H4: ='4.3 Geometric Imperfetion'!I3 -> Sofonias Bezabeh
B5: For the building to be categorized as being regular in plan, it shall satisfy all the conditions listed below
A7: 1 | B7: With respect to the lateral stiffness and mass distribution, the building structure shall be approximately symmetrical in plan with respect to the two orthogonal Direction.
B8: The building satisfied condition 1 requirment due to a lack of any L, C, H, I, and X shape. It almost symetrical both ortogonal direction
A10: 2 | B10: The in-plan stiffness of the floors shall be sufficiently large in comparison with the lateral stiffness of the vertical structural elements, so that the deformation of the floor shall have a small effect on the distribution of the forces among the vertical structural elements.
B11: →The horizonal displacement of the floor due to seismic action do not exceed anywhere by more than 10% of the corresponding absolute horizontal displacement that would result form a rigid diaphram assumption.
B12: →Slab thickness is greater than 70mm.
B13: →The minimum reinforcement requirmnet of eurocode 2 is applied for both ortogonal direction.
B14: Therefore the structure satisfies condition 2 Plan regularity Criterion
A15: 3 | B15: The slenderness (l) = Lmax/Lmin of the building in plan shall be not higher than 4, where Lmax and Lmin are respectively the larger and smaller in plan dimension of the building, measured in orthogonal directions.
B17: Story | C17: Lmax (m) | D17: Lmin (m) | E17: λ
B18: ='STORY DATA'!B5 -> ROOF FL | C18: 33.5 | D18: 22.5 | E18: =C18/D18 -> 1.4888889 | F18: =IF(E18<4,"OK","NOT OK") -> OK
B19: ='STORY DATA'!B6 -> 9TH FL | C19: 33.5 | D19: 22.5 | E19: =C19/D19 -> 1.4888889 | F19: =IF(E19<4,"OK","NOT OK") -> OK
B20: ='STORY DATA'!B7 -> 8TH FL | C20: 33.5 | D20: 22.5 | E20: =C20/D20 -> 1.4888889 | F20: =IF(E20<4,"OK","NOT OK") -> OK
B21: ='STORY DATA'!B8 -> 7TH FL | C21: 33.5 | D21: 22.5 | E21: =C21/D21 -> 1.4888889 | F21: =IF(E21<4,"OK","NOT OK") -> OK
B22: ='STORY DATA'!B9 -> 6TH FL | C22: 33.5 | D22: 22.5 | E22: =C22/D22 -> 1.4888889 | F22: =IF(E22<4,"OK","NOT OK") -> OK
B23: ='STORY DATA'!B10 -> 5TH FL | C23: 33.5 | D23: 22.5 | E23: =C23/D23 -> 1.4888889 | F23: =IF(E23<4,"OK","NOT OK") -> OK
B24: ='STORY DATA'!B11 -> 4TH FL | C24: 33.5 | D24: 22.5 | E24: =C24/D24 -> 1.4888889 | F24: =IF(E24<4,"OK","NOT OK") -> OK
B25: ='STORY DATA'!B12 -> 3RD FL | C25: 33.5 | D25: 22.5 | E25: =C25/D25 -> 1.4888889 | F25: =IF(E25<4,"OK","NOT OK") -> OK
B26: ='STORY DATA'!B13 -> 2ND FL | C26: 33.5 | D26: 22.5 | E26: =C26/D26 -> 1.4888889 | F26: =IF(E26<4,"OK","NOT OK") -> OK
B27: ='STORY DATA'!B14 -> 1ST FL | C27: 33.5 | D27: 22.5 | E27: =C27/D27 -> 1.4888889 | F27: =IF(E27<4,"OK","NOT OK") -> OK
B28: ='STORY DATA'!B15 -> GROUND FL | C28: 33.5 | D28: 22.5 | E28: =C28/D28 -> 1.4888889 | F28: =IF(E28<4,"OK","NOT OK") -> OK
B30: Table 3.2.1: | C30: Slenderness of the Building
B32: The structure is regualr in Plan
A34: 4 | B34: Structural Eccentricity Shall be less than 30% of the torsional radius of the building
B76: Structural Eccentricity
B78: Story | C78: Xcm (m) | D78: Ycm (m) | E78: Xcr (m) | F78: Ycr (m) | G78: eox (m) | H78: eoy(m)
B79: =+B18 -> ROOF FL | C79: =+VLOOKUP($B79,'Center of Mass'!$B$8:$M82,9,0) -> 9.198 | D79: =+VLOOKUP($B79,'Center of Mass'!$B$8:$M82,10,0) -> 16.383 | E79: =+VLOOKUP($B79,'Center of Mass'!$B$8:$M82,11,0) -> 10.413 | F79: =+VLOOKUP($B79,'Center of Mass'!$B$8:$M82,12,0) -> 17.472 | G79: =C79-E79 -> -1.215 | H79: =D79-F79 -> -1.089
B80: =+B19 -> 9TH FL | C80: =+VLOOKUP($B80,'Center of Mass'!$B$8:$M83,9,0) -> 9.155 | D80: =+VLOOKUP($B80,'Center of Mass'!$B$8:$M83,10,0) -> 16.373 | E80: =+VLOOKUP($B80,'Center of Mass'!$B$8:$M83,11,0) -> 10.326 | F80: =+VLOOKUP($B80,'Center of Mass'!$B$8:$M83,12,0) -> 17.326 | G80: =C80-E80 -> -1.171 | H80: =D80-F80 -> -0.953
B81: =+B20 -> 8TH FL | C81: =+VLOOKUP($B81,'Center of Mass'!$B$8:$M84,9,0) -> 9.155 | D81: =+VLOOKUP($B81,'Center of Mass'!$B$8:$M84,10,0) -> 16.37 | E81: =+VLOOKUP($B81,'Center of Mass'!$B$8:$M84,11,0) -> 10.28 | F81: =+VLOOKUP($B81,'Center of Mass'!$B$8:$M84,12,0) -> 17.271 | G81: =C81-E81 -> -1.125 | H81: =D81-F81 -> -0.901
B82: =+B21 -> 7TH FL | C82: =+VLOOKUP($B82,'Center of Mass'!$B$8:$M85,9,0) -> 9.155 | D82: =+VLOOKUP($B82,'Center of Mass'!$B$8:$M85,10,0) -> 16.367 | E82: =+VLOOKUP($B82,'Center of Mass'!$B$8:$M85,11,0) -> 10.226 | F82: =+VLOOKUP($B82,'Center of Mass'!$B$8:$M85,12,0) -> 17.196 | G82: =C82-E82 -> -1.071 | H82: =D82-F82 -> -0.829
B83: =+B22 -> 6TH FL | C83: =+VLOOKUP($B83,'Center of Mass'!$B$8:$M86,9,0) -> 9.156 | D83: =+VLOOKUP($B83,'Center of Mass'!$B$8:$M86,10,0) -> 16.375 | E83: =+VLOOKUP($B83,'Center of Mass'!$B$8:$M86,11,0) -> 10.166 | F83: =+VLOOKUP($B83,'Center of Mass'!$B$8:$M86,12,0) -> 17.092 | G83: =C83-E83 -> -1.01 | H83: =D83-F83 -> -0.717
B84: =+B23 -> 5TH FL | C84: =+VLOOKUP($B84,'Center of Mass'!$B$8:$M87,9,0) -> 9.16 | D84: =+VLOOKUP($B84,'Center of Mass'!$B$8:$M87,10,0) -> 16.374 | E84: =+VLOOKUP($B84,'Center of Mass'!$B$8:$M87,11,0) -> 10.106 | F84: =+VLOOKUP($B84,'Center of Mass'!$B$8:$M87,12,0) -> 16.948 | G84: =C84-E84 -> -0.946 | H84: =D84-F84 -> -0.574
B85: =+B24 -> 4TH FL | C85: =+VLOOKUP($B85,'Center of Mass'!$B$8:$M88,9,0) -> 9.158 | D85: =+VLOOKUP($B85,'Center of Mass'!$B$8:$M88,10,0) -> 16.391 | E85: =+VLOOKUP($B85,'Center of Mass'!$B$8:$M88,11,0) -> 10.054 | F85: =+VLOOKUP($B85,'Center of Mass'!$B$8:$M88,12,0) -> 16.752 | G85: =C85-E85 -> -0.896 | H85: =D85-F85 -> -0.361
B86: =+B25 -> 3RD FL | C86: =+VLOOKUP($B86,'Center of Mass'!$B$8:$M89,9,0) -> 9.151 | D86: =+VLOOKUP($B86,'Center of Mass'!$B$8:$M89,10,0) -> 16.419 | E86: =+VLOOKUP($B86,'Center of Mass'!$B$8:$M89,11,0) -> 10.022 | F86: =+VLOOKUP($B86,'Center of Mass'!$B$8:$M89,12,0) -> 16.443 | G86: =C86-E86 -> -0.871 | H86: =D86-F86 -> -0.024
B87: =+B26 -> 2ND FL | C87: =+VLOOKUP($B87,'Center of Mass'!$B$8:$M90,9,0) -> 9.137 | D87: =+VLOOKUP($B87,'Center of Mass'!$B$8:$M90,10,0) -> 16.42 | E87: =+VLOOKUP($B87,'Center of Mass'!$B$8:$M90,11,0) -> 10.021 | F87: =+VLOOKUP($B87,'Center of Mass'!$B$8:$M90,12,0) -> 15.984 | G87: =C87-E87 -> -0.884 | H87: =D87-F87 -> 0.436
B88: =+B27 -> 1ST FL | C88: =+VLOOKUP($B88,'Center of Mass'!$B$8:$M91,9,0) -> 9.072 | D88: =+VLOOKUP($B88,'Center of Mass'!$B$8:$M91,10,0) -> 16.512 | E88: =+VLOOKUP($B88,'Center of Mass'!$B$8:$M91,11,0) -> 10.305 | F88: =+VLOOKUP($B88,'Center of Mass'!$B$8:$M91,12,0) -> 15.466 | G88: =C88-E88 -> -1.233 | H88: =D88-F88 -> 1.046
B89: =+B28 -> GROUND FL | C89: =+VLOOKUP($B89,'Center of Mass'!$B$8:$M92,9,0) -> 7.539 | D89: =+VLOOKUP($B89,'Center of Mass'!$B$8:$M92,10,0) -> 16.069 | E89: =+VLOOKUP($B89,'Center of Mass'!$B$8:$M92,11,0) -> 10.924 | F89: =+VLOOKUP($B89,'Center of Mass'!$B$8:$M92,12,0) -> 16.484 | G89: =C89-E89 -> -3.385 | H89: =D89-F89 -> -0.415
...

Sheet 3.3 Lateral Force Participation
C1: 3.3. | D1: Building Classification | G1: Project : | H1: =+DISPLACEMENT!C1 -> BAHRU SARBET MODEL 1-3 q=1
G2: Client : | H2: =+DISPLACEMENT!C2 -> ATO BAHRU
G3: Designed by : | H3: =+DISPLACEMENT!C4 -> Sofonias Bezabeh
D5: During Seismic action building behaves based on the type of lateral force resisting system attached to it. Based on a mechanism the structure responds during seismic action, classified into various categories
C7: 1 | D7: Frame system
D8: If more than 65% of the total base Shear forces resisted by a frame action of Primary Seismic columns and beams, the structure would classify under frame system.
C9: 2 | D9: Wall system
D10: For a structure More than 65% of the total base shear force captured by a Primary shear wall. It is further classified as coupled and uncoupled wall based on the arrangement of a shear walls
C11: 3 | D11: Dual System
D12: In this case both Primary Seismic frame and wall contributed for a resistance of seismic lateral force. It is classified into two based on the amount of force captured by Primary Seismic Frame and Wall members.
D14: Dual System classification
D15: Classification | E15: Frame Equivalent Dual system | G15: Wall equivalent dual system
D16: Justification | E16: More than 50% of a lateral force captured by frame action | G16: More than 50% of a lateral force captured by wall action
C18: 4 | D18: Torsionally Flexible system
D19: For a building whose Radius of gyration of the floor mass exceeds the torsional radius in one or both of the two main direction of the building in plan.
C20: 5 | D20: Inverted pendulum system
D21: A system with at least 50% of the total mass in the upper third of the height, or with energy dissipation at the base of a single element.
D23: Stiffness Contribution and Lateral Force Attraction | K23: Displacement Load Used
K24: UL1 | L24: UL2
H25: Per Floor Load Resistance
E26: Along X-Direction | H26: UL1
D27: Story | E27: Lateral Load | F27: Column Load | G27: Shear Wall Load | H27: Column Load | I27: Shear Wall Load
D28: =+'STORY DATA'!B5 -> ROOF FL | E28: {=ABS(+INDEX('STOREY SHEARS'!$B$9:$J$5385,MATCH(D28&$K$24,'STOREY SHEARS'!$B$9:$B5392&'STOREY SHEARS'!$C$9:$C5392,0),5))} -> 200000 | F28: =ABS(+SUMIF('Column Forces'!$A$2:$K9869,CONCATENATE(D28,$K$24,0),'Column Forces'!$G$2:$G9869)) -> 70870.41 | G28: =ABS(SUMIF('Shear Wall Forces'!$A$2:K2327,CONCATENATE(D28,$K$24,"Bottom"),'Shear Wall Forces'!$H$2:H2327)) -> 29129.58 | H28: =+F28/E28 -> 0.35435205 | I28: =+G28/E28 -> 0.1456479
D29: =+'STORY DATA'!B6 -> 9TH FL | E29: {=ABS(+INDEX('STOREY SHEARS'!$B$9:$J$5385,MATCH(D29&$K$24,'STOREY SHEARS'!$B$9:$B5393&'STOREY SHEARS'!$C$9:$C5393,0),5))} -> 400000 | F29: =ABS(+SUMIF('Column Forces'!$A$2:$K9870,CONCATENATE(D29,$K$24,0),'Column Forces'!$G$2:$G9870)) -> 194432.93 | G29: =ABS(SUMIF('Shear Wall Forces'!$A$2:K2328,CONCATENATE(D29,$K$24,"Bottom"),'Shear Wall Forces'!$H$2:H2328)) -> 443261.75 | H29: =+F29/E29 -> 0.48608233 | I29: =+G29/E29 -> 1.1081544
D30: =+'STORY DATA'!B7 -> 8TH FL | E30: {=ABS(+INDEX('STOREY SHEARS'!$B$9:$J$5385,MATCH(D30&$K$24,'STOREY SHEARS'!$B$9:$B5394&'STOREY SHEARS'!$C$9:$C5394,0),5))} -> 500000 | F30: =ABS(+SUMIF('Column Forces'!$A$2:$K9871,CONCATENATE(D30,$K$24,0),'Column Forces'!$G$2:$G9871)) -> 213849.08 | G30: =ABS(SUMIF('Shear Wall Forces'!$A$2:K2329,CONCATENATE(D30,$K$24,"Bottom"),'Shear Wall Forces'!$H$2:H2329)) -> 486925.4 | H30: =+F30/E30 -> 0.42769816 | I30: =+G30/E30 -> 0.9738508
D31: =+'STORY DATA'!B8 -> 7TH FL | E31: {=ABS(+INDEX('STOREY SHEARS'!$B$9:$J$5385,MATCH(D31&$K$24,'STOREY SHEARS'!$B$9:$B5395&'STOREY SHEARS'!$C$9:$C5395,0),5))} -> 600000 | F31: =ABS(+SUMIF('Column Forces'!$A$2:$K9872,CONCATENATE(D31,$K$24,0),'Column Forces'!$G$2:$G9872)) -> 234563.83 | G31: =ABS(SUMIF('Shear Wall Forces'!$A$2:K2330,CONCATENATE(D31,$K$24,"Bottom"),'Shear Wall Forces'!$H$2:H2330)) -> 599873.82 | H31: =+F31/E31 -> 0.39093972 | I31: =+G31/E31 -> 0.9997897
D32: =+'STORY DATA'!B9 -> 6TH FL | E32: {=ABS(+INDEX('STOREY SHEARS'!$B$9:$J$5385,MATCH(D32&$K$24,'STOREY SHEARS'!$B$9:$B5396&'STOREY SHEARS'!$C$9:$C5396,0),5))} -> 700000 | F32: =ABS(+SUMIF('Column Forces'!$A$2:$K9873,CONCATENATE(D32,$K$24,0),'Column Forces'!$G$2:$G9873)) -> 502368.64 | G32: =ABS(SUMIF('Shear Wall Forces'!$A$2:K2331,CONCATENATE(D32,$K$24,"Bottom"),'Shear Wall Forces'!$H$2:H2331)) -> 525167.03 | H32: =+F32/E32 -> 0.71766949 | I32: =+G32/E32 -> 0.75023861
D33: =+'STORY DATA'!B10 -> 5TH FL | E33: {=ABS(+INDEX('STOREY SHEARS'!$B$9:$J$5385,MATCH(D33&$K$24,'STOREY SHEARS'!$B$9:$B5397&'STOREY SHEARS'!$C$9:$C5397,0),5))} -> 800000 | F33: =ABS(+SUMIF('Column Forces'!$A$2:$K9874,CONCATENATE(D33,$K$24,0),'Column Forces'!$G$2:$G9874)) -> 720760.63 | G33: =ABS(SUMIF('Shear Wall Forces'!$A$2:K2332,CONCATENATE(D33,$K$24,"Bottom"),'Shear Wall Forces'!$H$2:H2332)) -> 435408.37 | H33: =+F33/E33 -> 0.90095079 | I33: =+G33/E33 -> 0.54426046
D34: =+'STORY DATA'!B11 -> 4TH FL | E34: {=ABS(+INDEX('STOREY SHEARS'!$B$9:$J$5385,MATCH(D34&$K$24,'STOREY SHEARS'!$B$9:$B5398&'STOREY SHEARS'!$C$9:$C5398,0),5))} -> 900000 | F34: =ABS(+SUMIF('Column Forces'!$A$2:$K9875,CONCATENATE(D34,$K$24,0),'Column Forces'!$G$2:$G9875)) -> 646904.79 | G34: =ABS(SUMIF('Shear Wall Forces'!$A$2:K2333,CONCATENATE(D34,$K$24,"Bottom"),'Shear Wall Forces'!$H$2:H2333)) -> 345755.75 | H34: =+F34/E34 -> 0.7187831 | I34: =+G34/E34 -> 0.38417306
D35: =+'STORY DATA'!B12 -> 3RD FL | E35: {=ABS(+INDEX('STOREY SHEARS'!$B$9:$J$5385,MATCH(D35&$K$24,'STOREY SHEARS'!$B$9:$B5399&'STOREY SHEARS'!$C$9:$C5399,0),5))} -> 1000000 | F35: =ABS(+SUMIF('Column Forces'!$A$2:$K9876,CONCATENATE(D35,$K$24,0),'Column Forces'!$G$2:$G9876)) -> 673431.95 | G35: =ABS(SUMIF('Shear Wall Forces'!$A$2:K2334,CONCATENATE(D35,$K$24,"Bottom"),'Shear Wall Forces'!$H$2:H2334)) -> 387178.59 | H35: =+F35/E35 -> 0.67343195 | I35: =+G35/E35 -> 0.38717859
D36: =+'STORY DATA'!B13 -> 2ND FL | E36: {=ABS(+INDEX('STOREY SHEARS'!$B$9:$J$5385,MATCH(D36&$K$24,'STOREY SHEARS'!$B$9:$B5400&'STOREY SHEARS'!$C$9:$C5400,0),5))} -> 1100000 | F36: =ABS(+SUMIF('Column Forces'!$A$2:$K9877,CONCATENATE(D36,$K$24,0),'Column Forces'!$G$2:$G9877)) -> 702729.19 | G36: =ABS(SUMIF('Shear Wall Forces'!$A$2:K2335,CONCATENATE(D36,$K$24,"Bottom"),'Shear Wall Forces'!$H$2:H2335)) -> 503781.75 | H36: =+F36/E36 -> 0.63884472 | I36: =+G36/E36 -> 0.45798341
D37: =+'STORY DATA'!B14 -> 1ST FL | E37: {=ABS(+INDEX('STOREY SHEARS'!$B$9:$J$5385,MATCH(D37&$K$24,'STOREY SHEARS'!$B$9:$B5401&'STOREY SHEARS'!$C$9:$C5401,0),5))} -> 1200000 | F37: =ABS(+SUMIF('Column Forces'!$A$2:$K9878,CONCATENATE(D37,$K$24,0),'Column Forces'!$G$2:$G9878)) -> 1015797.7 | G37: =ABS(SUMIF('Shear Wall Forces'!$A$2:K2336,CONCATENATE(D37,$K$24,"Bottom"),'Shear Wall Forces'!$H$2:H2336)) -> 451563.63 | H37: =+F37/E37 -> 0.84649807 | I37: =+G37/E37 -> 0.37630303
D38: =+'STORY DATA'!B15 -> GROUND FL | E38: {=ABS(+INDEX('STOREY SHEARS'!$B$9:$J$5385,MATCH(D38&$K$24,'STOREY SHEARS'!$B$9:$B5424&'STOREY SHEARS'!$C$9:$C5424,0),5))} -> 1300000 | F38: =ABS(+SUMIF('Column Forces'!$A$2:$K9884,CONCATENATE(D38,$K$24,0),'Column Forces'!$G$2:$G9884)) -> 696549.52 | G38: =ABS(SUMIF('Shear Wall Forces'!$A$2:K2342,CONCATENATE(D38,$K$24,"Bottom"),'Shear Wall Forces'!$H$2:H2342)) -> 526092.1 | H38: =+F38/E38 -> 0.53580732 | I38: =+G38/E38 -> 0.40468623
D40: Load Participation | F40: =+F38/E38 -> 0.53580732 | G40: =+G38/E38 -> 0.40468623
